package Day_46_Exception;

public class TryCatch {
    public static void main(String[] args) {

        try {
            // hata alınması beklenen kod bloğu
        }catch (Exception e){
            // hata alındıktan sonra yapılan işlem

        }


//        System.out.println("program basladi");
//        try {// hata alınması beklenen kod bloğu                       // burası hatasız
//            System.out.println("try blogu ici");
//            int x=5/1;
//        }catch (Exception e){// hata alındıktan sonra yapılan işlem
//            System.out.println("catch blogunun ici");
//        }
//        System.out.println("program sonlandi");




//        System.out.println("program basladi");         // burada hata var ve catch bloğunun içine giriyor.
//        try {// hata alınması beklenen kod bloğu
//            System.out.println("try blogu ici");
//            int x=5/0;
//        }catch (Exception e){// hata alındıktan sonra yapılan işlem
//            System.out.println("catch blogunun ici");
//        }
//        System.out.println("program sonlandi");






    }

}
